Workbook

Sheet Data
A1: Order_ID | B1: Date | C1: Customer | D1: Product | E1: Category | F1: Sales | G1: Quantity | H1: Region | I1: Revenue per Item | J1: Order Size
A2: 1001 | B2: 45292 | C2: Rahul | D2: Laptop | E2: Electronics | F2: 55000 | G2: 1 | H2: East | I2: =F2/G2 -> 55000 | J2: =IF(F2>20000, "High", "Low") -> High
A3: 1002 | B3: 45293 | C3: Amit | D3: Phone | E3: Electronics | F3: 18000 | G3: 1 | H3: West | I3: =F3/G3 -> 18000 | J3: =IF(F3>20000, "High", "Low") -> Low
A4: 1003 | B4: 45294 | C4: Neha | D4: Shoes | E4: Fashion | F4: 3000 | G4: 2 | H4: North | I4: =F4/G4 -> 1500 | J4: =IF(F4>20000, "High", "Low") -> Low
A5: 1004 | B5: 45295 | C5: Priya | D5: Jacket | E5: Fashion | F5: 4000 | G5: 1 | H5: East | I5: =F5/G5 -> 4000 | J5: =IF(F5>20000, "High", "Low") -> Low
A6: 1005 | B6: 45296 | C6: Arjun | D6: Headphones | E6: Electronics | F6: 2500 | G6: 1 | H6: South | I6: =F6/G6 -> 2500 | J6: =IF(F6>20000, "High", "Low") -> Low
A7: 1006 | B7: 45297 | C7: Ravi | D7: Table | E7: Furniture | F7: 15000 | G7: 1 | H7: West | I7: =F7/G7 -> 15000 | J7: =IF(F7>20000, "High", "Low") -> Low
A8: 1007 | B8: 45298 | C8: Sneha | D8: Chair | E8: Furniture | F8: 8000 | G8: 2 | H8: North | I8: =F8/G8 -> 4000 | J8: =IF(F8>20000, "High", "Low") -> Low
A9: 1008 | B9: 45299 | C9: Karan | D9: Laptop | E9: Electronics | F9: 55000 | G9: 1 | H9: South | I9: =F9/G9 -> 55000 | J9: =IF(F9>20000, "High", "Low") -> High
A10: 1009 | B10: 45300 | C10: Meena | D10: Shoes | E10: Fashion | F10: 3000 | G10: 1 | H10: East | I10: =F10/G10 -> 3000 | J10: =IF(F10>20000, "High", "Low") -> Low
A11: 1010 | B11: 45301 | C11: Vikram | D11: Phone | E11: Electronics | F11: 18000 | G11: 2 | H11: North | I11: =F11/G11 -> 9000 | J11: =IF(F11>20000, "High", "Low") -> Low

Sheet Pivot Table
A2: 📊 A. Sales by Category
B3: Row Labels | C3: Sum of Sales
B4: Electronics | C4: 148500
B5: Furniture | C5: 23000
B6: Fashion | C6: 10000
B7: Grand Total | C7: 181500
A10: 📊 B. Sales by Region
B11: Row Labels | C11: Sum of Sales
B12: East | C12: 0.3415978
B13: South | C13: 0.31680441
B14: West | C14: 0.18181818
B15: North | C15: 0.15977961
B16: Grand Total | C16: 1
A19: 📊 C. Sales Trend by Date
B20: Row Labels | C20: Sum of Sales
B21: 45292 | C21: 55000
B22: 45293 | C22: 18000
B23: 45294 | C23: 3000
B24: 45295 | C24: 4000
B25: 45296 | C25: 2500
B26: 45297 | C26: 15000
B27: 45298 | C27: 8000
B28: 45299 | C28: 55000
B29: 45300 | C29: 3000
B30: 45301 | C30: 18000
B31: Grand Total | C31: 181500
A34: 📊 D. Top Customers
B35: Row Labels | C35: Sum of Sales
B36: Rahul | C36: 55000
B37: Karan | C37: 55000
B38: Vikram | C38: 18000
B39: Amit | C39: 18000
B40: Grand Total | C40: 146000
B51: Row Labels | C51: Sum of Sales | D51: Sum of Quantity
B52: Electronics | C52: 148500 | D52: 6
B53: Phone | C53: 36000 | D53: 3
B54: Laptop | C54: 110000 | D54: 2
B55: Headphones | C55: 2500 | D55: 1
B56: Fashion | C56: 10000 | D56: 4
B57: Shoes | C57: 6000 | D57: 3
...

Sheet Dashboard
P3: Row Labels | Q3: Sum of Sales
P4: Rahul | Q4: 55000
P5: Karan | Q5: 55000
P6: Vikram | Q6: 18000
P7: Amit | Q7: 18000
P8: Grand Total | Q8: 146000
P10: =Pivot!A36 | Q10: =Pivot!B36
P11: ='Pivot Table'!B36 -> Rahul | Q11: =GETPIVOTDATA("Sales",'Pivot Table'!$B$35,"Customer","Rahul") -> 55000
P12: ='Pivot Table'!B37 -> Karan | Q12: =GETPIVOTDATA("Sales",'Pivot Table'!$B$35,"Customer","Rahul") -> 55000
P13: ='Pivot Table'!B38 -> Vikram | Q13: =GETPIVOTDATA("Sales",'Pivot Table'!$B$35,"Customer","Rahul") -> 55000
